Workbook

Sheet Instrucciones
B2: TSTE · Carga de clubes
B4: Dos hojas: CLUBES (una fila por club) y FUENTES (una fila por fuente de contenido).
B5: Están vinculadas por el campo id: el id que pongas en Clubes es el que va en la columna club_id de Fuentes.
B7: QUÉ COMPLETÁS VOS (celdas en amarillo)
B8: Lo que sabe un hincha y no se puede averiguar solo: colores, patrón de la camiseta, estrellas, apodos, las trampas de desambiguación, y sobre todo QUÉ FUENTES SEGUIR. Esa curaduría es el trabajo real.
B10: QUÉ NO COMPLETES (celdas en gris)
B11: El channelId de YouTube, la URL exacta del RSS, el id de API-Football y el formato del feed los resuelvo yo a partir del arroba o del sitio. Si los cargás a mano vas a perder horas y a equivocarte.
B13: CÓMO CARGAR UNA FUENTE
B14: En url_o_handle alcanza con: el arroba de YouTube (@la1913oficial), el link de una playlist, o el dominio del medio (lavozdelinterior.com.ar). Yo busco el feed y verifico que esté vivo.
B16: EL ORDEN IMPORTA
B17: Cargá primero DOS O TRES clubes completos y avisame. Los corro por el pipeline y confirmamos que el esquema aguanta antes de que cargues treinta. Si algo falta, es mejor descubrirlo en la fila 3 que en la 30.
B19: Los 30 clubes de Primera 2026 ya están cargados con su id de API-Football y su ciudad cuando el nombre la dice. Talleres viene completo como ejemplo: mirá esa fila antes de empezar.
B21: Clubes cargados: | C21: =COUNTA(Clubes!A3:A200) -> 30
B22: Fuentes cargadas: | C22: =COUNTA(Fuentes!A3:A400) -> 10
B23: Clubes sin ninguna fuente: | C23: =COUNTIFS(Clubes!A3:A200,"<>",Clubes!L3:L200,0) -> 29

Sheet Listas
A1: patron | B1: tipo | C1: plataforma | D1: filtro | E1: contexto
A2: bastones | B2: oficial | C2: youtube | D2: ninguno | E2: deportes
A3: franja | B3: medio | C3: rss | D3: titulo | E3: general
A4: banda | B4: hinchas | C4: sitio | D4: texto
A5: mitades | B5: periodista
A6: liso | B6: analista

Sheet Clubes
A1: id | B1: nombre | C1: nombre_completo | D1: ciudad | E1: color_1 | F1: color_2 | G1: patron | H1: estrellas | I1: apodos | J1: bloqueadores | K1: apiFootballTeamId | L1: fuentes_cargadas | M1: notas
A2: minúsculas y guiones. ej: talleres-cba | B2: como lo dice el hincha | C2: el nombre legal, para desambiguar | E2: hex del color principal. ej: #0A3D91 | F2: hex del segundo color | G2: cómo es la camiseta | H2: cuántas lleva el escudo. 0 si no lleva | I2: separados por coma. ej: la T, el Matador, Albiazul | J2: LO MÁS IMPORTANTE: con qué se confunde el nombre. ej: Remedios de Escalada, Perico, taller mecánico | K2: lo completo yo | L2: se calcula solo
A3: talleres-cba | B3: Talleres | C3: Club Atlético Talleres (Córdoba) | D3: Córdoba | E3: #0A3D91 | F3: #FFFFFF | G3: bastones | H3: 2 | I3: la T, el Matador, Albiazul, los Tallarines | J3: Remedios de Escalada, Talleres RE, Perico, taller mecánico, talleres municipales, Tigre | K3: 456 | L3: =IF(A3="","",COUNTIF(Fuentes!A:A,A3)) -> 10 | M3: Ejemplo completo. Ojo: 'el Matador' también es Tigre, por eso Tigre va de bloqueador.
A4: aldosivi | B4: Aldosivi | C4: Club Atlético Aldosivi | D4: Mar del Plata | E4: Verde | F4: Amarillo | G4: bastones | H4: 0 | I4: El Tiburón | K4: 463 | L4: =IF(A4="","",COUNTIF(Fuentes!A:A,A4)) -> 0 | M4: API-Football lo llama: Aldosivi
A5: argentinos | B5: Argentinos | C5: Asociación Atlética Argentinos Juniors | E5: Rojo | F5: Blanco | G5: banda | H5: 5 | I5: El bicho, el semillero del mundo | K5: 458 | L5: =IF(A5="","",COUNTIF(Fuentes!A:A,A5)) -> 0 | M5: API-Football lo llama: Argentinos JRS
A6: atl-tucuman | B6: Atlético Tucumán | C6: Club Atlético Tucumán | D6: Tucumán | E6: Celeste | F6: Blanco | G6: bastones | H6: 1 | I6: El decano | K6: 455 | L6: =IF(A6="","",COUNTIF(Fuentes!A:A,A6)) -> 0 | M6: API-Football lo llama: Atletico Tucuman
A7: banfield | B7: Banfield | C7: Club Atlético Banfield | E7: Verde | F7: Blanco | G7: bastones | H7: 2 | I7: El taladro | K7: 449 | L7: =IF(A7="","",COUNTIF(Fuentes!A:A,A7)) -> 0 | M7: API-Football lo llama: Banfield
A8: barracas | B8: Barracas Central | C8: Club Atlético Barracas Central | E8: Rojo | F8: Blanco | G8: bastones | H8: 0 | I8: El guapo | K8: 2432 | L8: =IF(A8="","",COUNTIF(Fuentes!A:A,A8)) -> 0 | M8: API-Football lo llama: Barracas Central
A9: belgrano-cba | B9: Belgrano | C9: Club Atlético Belgrano | D9: Córdoba | E9: Celeste | G9: liso | H9: 1 | I9: Pirata | K9: 440 | L9: =IF(A9="","",COUNTIF(Fuentes!A:A,A9)) -> 0 | M9: API-Football lo llama: Belgrano Cordoba
A10: boca | B10: Boca | C10: Club Atlético Boca Juniors | E10: Azul | F10: Amarillo | G10: franja | H10: 74 | I10: Xeneixe, bostero, azul y oro | K10: 451 | L10: =IF(A10="","",COUNTIF(Fuentes!A:A,A10)) -> 0 | M10: API-Football lo llama: Boca Juniors
A11: central-cordoba-sde | B11: Central Córdoba | C11: club Atlético Central Córdoba | D11: Santiago del Estero | E11: Negro | F11: Blanco | G11: bastones | H11: 1 | I11: El ferroviario | K11: 1065 | L11: =IF(A11="","",COUNTIF(Fuentes!A:A,A11)) -> 0 | M11: API-Football lo llama: Central Cordoba de Santiago
A12: defensa | B12: Defensa y Justicia | C12: Club social y deportivo Defensa y justicia | E12: Verde | F12: Amarillo | G12: banda | H12: 2 | I12: El halcón de Varela | K12: 442 | L12: =IF(A12="","",COUNTIF(Fuentes!A:A,A12)) -> 0 | M12: API-Football lo llama: Defensa Y Justicia
A13: riestra | B13: Riestra | C13: Deportivo Riestra Asociación de fomento Barrio Colón | E13: Negro | F13: Blanco | G13: liso | H13: 0 | I13: El malevo | K13: 476 | L13: =IF(A13="","",COUNTIF(Fuentes!A:A,A13)) -> 0 | M13: API-Football lo llama: Deportivo Riestra
A14: estudiantes-rc | B14: Estudiantes (RC) | C14: Asociación Atlética Estudiantes | D14: Río Cuarto | E14: Celeste | G14: liso | H14: 0 | I14: Leones | K14: 2424 | L14: =IF(A14="","",COUNTIF(Fuentes!A:A,A14)) -> 0 | M14: API-Football lo llama: Estudiantes de Rio Cuarto
A15: estudiantes-lp | B15: Estudiantes | C15: Club estudiantes de La plata | D15: La Plata | E15: Rojo | F15: Blanco | G15: bastones | H15: 1 | I15: El pincha, Pincharrata | K15: 450 | L15: =IF(A15="","",COUNTIF(Fuentes!A:A,A15)) -> 0 | M15: API-Football lo llama: Estudiantes L.P.
A16: gimnasia-lp | B16: Gimnasia (LP) | C16: Club de Gimnasia y esgrima La plata | D16: La Plata | E16: Azul | F16: Blanco | G16: franja | H16: 0 | I16: El lobo | K16: 434 | L16: =IF(A16="","",COUNTIF(Fuentes!A:A,A16)) -> 0 | M16: API-Football lo llama: Gimnasia L.P.
A17: gimnasia-mza | B17: Gimnasia (M) | C17: Club atlético Gimnasia y esgrima | D17: Mendoza | E17: Negro | F17: BLanco | G17: bastones | H17: 0 | I17: Lobo mendocino | K17: 1066 | L17: =IF(A17="","",COUNTIF(Fuentes!A:A,A17)) -> 0 | M17: API-Football lo llama: Gimnasia M.
A18: huracan | B18: Huracán | C18: Club Atlético Huracan | E18: Blanco | F18: Rojo | G18: liso | H18: 0 | I18: El globo, el quemero, la quema | K18: 445 | L18: =IF(A18="","",COUNTIF(Fuentes!A:A,A18)) -> 0 | M18: API-Football lo llama: Huracan
A19: independiente-rivadavia | B19: Independiente Rivadavia | C19: Club Sportivo Independiente Rivadavia | D19: Mendoza | E19: Azul | F19: Blanco | G19: liso | H19: 1 | I19: la lepra mendocina | J19: lepra tambien le dicen a newells | K19: 473 | L19: =IF(A19="","",COUNTIF(Fuentes!A:A,A19)) -> 0 | M19: API-Football lo llama: Independ. Rivadavia
A20: independiente | B20: Independiente | C20: Club Atlético Independiente | E20: Rojo | G20: liso | I20: El diablo | K20: 453 | L20: =IF(A20="","",COUNTIF(Fuentes!A:A,A20)) -> 0 | M20: API-Football lo llama: Independiente
A21: instituto-cba | B21: Instituto | C21: Instituto Atlético Central Córdoba | D21: Córdoba | E21: Rojo | F21: Blanco | G21: bastones | H21: 0 | I21: La gloria, el glorioso cordobés | K21: 478 | L21: =IF(A21="","",COUNTIF(Fuentes!A:A,A21)) -> 0 | M21: API-Football lo llama: Instituto Cordoba
A22: lanus | B22: Lanús | C22: Club Atlético Lanus | E22: Bordó | G22: liso | H22: 0 | I22: El granate | K22: 446 | L22: =IF(A22="","",COUNTIF(Fuentes!A:A,A22)) -> 0 | M22: API-Football lo llama: Lanus
A23: newells | B23: Newell's | C23: Club atlético newells old boys | D23: Rosario | E23: Negro | F23: Rojo | G23: mitades | H23: 0 | I23: La lepra | J23: lepra tambien le dicen a Independiente de mendoza | K23: 457 | L23: =IF(A23="","",COUNTIF(Fuentes!A:A,A23)) -> 0 | M23: API-Football lo llama: Newells Old Boys
A24: platense | B24: Platense | C24: Club Atlético Platense | E24: Marron | F24: Blanco | G24: franja | H24: 0 | I24: El calamar | K24: 1064 | L24: =IF(A24="","",COUNTIF(Fuentes!A:A,A24)) -> 0 | M24: API-Football lo llama: Platense
A25: racing | B25: Racing | C25: Racing club | E25: Celeste | F25: Blanco | G25: bastones | H25: 0 | I25: La academia | J25: Racing de córdoba | K25: 436 | L25: =IF(A25="","",COUNTIF(Fuentes!A:A,A25)) -> 0 | M25: API-Football lo llama: Racing Club
A26: river | B26: River | C26: Club Atlético River Plate | E26: Rojo | F26: Blanco | G26: banda | H26: 0 | I26: El millonario | J26: River plate de uruguay | K26: 435 | L26: =IF(A26="","",COUNTIF(Fuentes!A:A,A26)) -> 0 | M26: API-Football lo llama: River Plate
A27: rosario-central | B27: Rosario Central | C27: Club atlético rosario central | D27: Rosario | E27: Amarillo | F27: Azul | G27: bastones | H27: 8 | I27: canalla | K27: 437 | L27: =IF(A27="","",COUNTIF(Fuentes!A:A,A27)) -> 0 | M27: API-Football lo llama: Rosario Central
A28: san-lorenzo | B28: San Lorenzo | C28: Club Atlético San Lorenzo de Almagro | E28: Bordo | F28: Azul | G28: bastones | H28: 0 | I28: El santo, El matador de Boedo, El cuervo | K28: 460 | L28: =IF(A28="","",COUNTIF(Fuentes!A:A,A28)) -> 0 | M28: API-Football lo llama: San Lorenzo
A29: sarmiento | B29: Sarmiento | C29: Club atletico Sarmiento | D29: Junín | E29: Verde | G29: liso | H29: 0 | I29: El verde, el verdolaga | K29: 474 | L29: =IF(A29="","",COUNTIF(Fuentes!A:A,A29)) -> 0 | M29: API-Football lo llama: Sarmiento Junin
A30: tigre | B30: Tigre | C30: Club Atlético Tigre | E30: Rojo | F30: Azul | G30: franja | H30: 1 | I30: El matador de Victoria | K30: 452 | L30: =IF(A30="","",COUNTIF(Fuentes!A:A,A30)) -> 0 | M30: API-Football lo llama: Tigre
A31: union | B31: Unión | C31: Club Atlético Unión | D31: Santa Fe | E31: Rojo | F31: Blanco | G31: bastones | H31: 0 | I31: El tatengue | K31: 441 | L31: =IF(A31="","",COUNTIF(Fuentes!A:A,A31)) -> 0 | M31: API-Football lo llama: Union Santa Fe
A32: velez | B32: Vélez | C32: Club Atlético Velez Sarsfield | E32: Blanco | F32: Azul | G32: V | H32: 1 | I32: El fortin | K32: 438 | L32: =IF(A32="","",COUNTIF(Fuentes!A:A,A32)) -> 0 | M32: API-Football lo llama: Velez Sarsfield
L33: =IF(A33="","",COUNTIF(Fuentes!A:A,A33))
L34: =IF(A34="","",COUNTIF(Fuentes!A:A,A34))
L35: =IF(A35="","",COUNTIF(Fuentes!A:A,A35))
L36: =IF(A36="","",COUNTIF(Fuentes!A:A,A36))
L37: =IF(A37="","",COUNTIF(Fuentes!A:A,A37))
L38: =IF(A38="","",COUNTIF(Fuentes!A:A,A38))
L39: =IF(A39="","",COUNTIF(Fuentes!A:A,A39))
L40: =IF(A40="","",COUNTIF(Fuentes!A:A,A40))
...

Sheet Fuentes
A1: club_id | B1: nombre | C1: tipo | D1: plataforma | E1: url_o_handle | F1: filtro | G1: contexto | H1: peso | I1: resuelto | J1: notas
A2: el mismo id que pusiste en la hoja Clubes | B2: cómo se llama la fuente | C2: oficial / medio / hinchas / periodista / analista | D2: youtube / rss / sitio | E2: el arroba, el link de la playlist, o el dominio del medio. NO hace falta el channelId | F2: ninguno = todo lo que sale es del club · titulo = el título siempre lo nombra · texto = hay que desambiguar | G2: deportes = solo deporte · general = publica de todo | H2: 0 a 1. Cuánto te importa. 1 = la que leés primero | I2: lo completo yo: channelId, URL del feed, formato
A3: talleres-cba | B3: Canal Showsport · Talleres | C3: medio | D3: rss | E3: canalshowsport.com.ar/futbol/talleres/ | F3: ninguno | G3: deportes | H3: 1 | J3: Truco WordPress: cualquier categoría + /feed/ da el RSS de esa sección sola
A4: talleres-cba | B4: Talleres · sitio oficial | C4: oficial | D4: rss | E4: clubtalleres.com.ar | F4: ninguno | G4: deportes | H4: 0.9 | J4: Incluye femenino e institucional
A5: talleres-cba | B5: La 1913 | C5: hinchas | D5: youtube | E5: @la1913oficial | F5: ninguno | G5: deportes | H5: 1 | J5: Medio partidario acreditado desde 2014
A6: talleres-cba | B6: El Diario La T | C6: hinchas | D6: youtube | E6: https://www.youtube.com/playlist?list=PLC55Mqag2NmwZd4wwk1H6v4ER-pp0f-s7 | F6: ninguno | G6: deportes | H6: 1 | J6: Programa diario y numerado
A7: talleres-cba | B7: Nacho Castellano | C7: periodista | D7: youtube | E7: @nachocastellano_ | F7: ninguno | G7: deportes | H7: 1 | J7: Primicias
A8: talleres-cba | B8: Pablo Chucrel | C8: analista | D8: youtube | E8: @pablochucrel7 | F8: titulo | G8: deportes | H8: 0.9 | J8: Cubre varios clubes: por eso filtro por título
A9: talleres-cba | B9: Mundo Albiazul (La Voz) | C9: medio | D9: youtube | E9: https://www.youtube.com/playlist?list=PLe1HoJfB4goAesjdYrGjVvLDP8Ms7LnfF | F9: ninguno | G9: deportes | H9: 1 | J9: Playlist dedicada dentro de un canal general: sale monotemática gratis
A10: talleres-cba | B10: Hoy Día Córdoba · Deportes | C10: medio | D10: rss | E10: hoydia.com.ar/category/deportes/ | F10: texto | G10: deportes | H10: 0.6 | J10: De 20 notas, una es de Talleres. Necesita desambiguación
A11: talleres-cba | B11: El Doce | C11: medio | D11: sitio | E11: eldoce.tv | F11: texto | G11: general | H11: 0.8 | J11: Sin RSS clásico: se lee por su feed de Google News
A12: talleres-cba | B12: La Nueva Mañana | C12: medio | D12: sitio | E12: lmdiario.com.ar | F12: texto | G12: general | H12: 0.6 | J12: Sin RSS: se lee por news sitemap
